Workbook
Name valuation_implied_share_price: 'DCF'!$B$107
Name valuation_upside_downside: 'DCF'!$B$109
Name valuation_enterprise_value: 'DCF'!$B$102
Name valuation_equity_value: 'DCF'!$B$105

Sheet DCF
A1: Shopify Inc. (SHOP) DCF Model
A2: Ticker: SHOP | Currency: USD millions | Date: 2026-05-23 | Year end: Dec 31
A4: Case selector | B4: 2 | C4: Selected case | D4: =CHOOSE($B$4,"Bear","Base","Bull")
A7: Market data
A8: Current share price | B8: 103
A9: Shares outstanding (M) | B9: 1300
A10: Cash & investments | B10: 5740
A11: Total debt | B11: 179
A12: Market cap | B12: =B8*B9
A13: Net cash | B13: =B10-B11
A16: Selected projection assumptions
A17: Assumption | B17: 2026E | C17: 2027E | D17: 2028E | E17: 2029E | F17: 2030E | G17: 2031E | H17: 2032E | I17: 2033E | J17: 2034E | K17: 2035E
A18: Revenue growth | B18: =CHOOSE($B$4,B33,B45,B57) | C18: =CHOOSE($B$4,C33,C45,C57) | D18: =CHOOSE($B$4,D33,D45,D57) | E18: =CHOOSE($B$4,E33,E45,E57) | F18: =CHOOSE($B$4,F33,F45,F57) | G18: =CHOOSE($B$4,G33,G45,G57) | H18: =CHOOSE($B$4,H33,H45,H57) | I18: =CHOOSE($B$4,I33,I45,I57) | ... K18: =CHOOSE($B$4,K33,K45,K57)
A19: Gross margin | B19: =CHOOSE($B$4,B34,B46,B58) | C19: =CHOOSE($B$4,C34,C46,C58) | D19: =CHOOSE($B$4,D34,D46,D58) | E19: =CHOOSE($B$4,E34,E46,E58) | F19: =CHOOSE($B$4,F34,F46,F58) | G19: =CHOOSE($B$4,G34,G46,G58) | H19: =CHOOSE($B$4,H34,H46,H58) | I19: =CHOOSE($B$4,I34,I46,I58) | ... K19: =CHOOSE($B$4,K34,K46,K58)
A20: EBIT margin | B20: =CHOOSE($B$4,B35,B47,B59) | C20: =CHOOSE($B$4,C35,C47,C59) | D20: =CHOOSE($B$4,D35,D47,D59) | E20: =CHOOSE($B$4,E35,E47,E59) | F20: =CHOOSE($B$4,F35,F47,F59) | G20: =CHOOSE($B$4,G35,G47,G59) | H20: =CHOOSE($B$4,H35,H47,H59) | I20: =CHOOSE($B$4,I35,I47,I59) | ... K20: =CHOOSE($B$4,K35,K47,K59)
A21: Cash tax rate | B21: =CHOOSE($B$4,B36,B48,B60) | C21: =CHOOSE($B$4,C36,C48,C60) | D21: =CHOOSE($B$4,D36,D48,D60) | E21: =CHOOSE($B$4,E36,E48,E60) | F21: =CHOOSE($B$4,F36,F48,F60) | G21: =CHOOSE($B$4,G36,G48,G60) | H21: =CHOOSE($B$4,H36,H48,H60) | I21: =CHOOSE($B$4,I36,I48,I60) | ... K21: =CHOOSE($B$4,K36,K48,K60)
A22: D&A / revenue | B22: =CHOOSE($B$4,B37,B49,B61) | C22: =CHOOSE($B$4,C37,C49,C61) | D22: =CHOOSE($B$4,D37,D49,D61) | E22: =CHOOSE($B$4,E37,E49,E61) | F22: =CHOOSE($B$4,F37,F49,F61) | G22: =CHOOSE($B$4,G37,G49,G61) | H22: =CHOOSE($B$4,H37,H49,H61) | I22: =CHOOSE($B$4,I37,I49,I61) | ... K22: =CHOOSE($B$4,K37,K49,K61)
A23: CapEx / revenue | B23: =CHOOSE($B$4,B38,B50,B62) | C23: =CHOOSE($B$4,C38,C50,C62) | D23: =CHOOSE($B$4,D38,D50,D62) | E23: =CHOOSE($B$4,E38,E50,E62) | F23: =CHOOSE($B$4,F38,F50,F62) | G23: =CHOOSE($B$4,G38,G50,G62) | H23: =CHOOSE($B$4,H38,H50,H62) | I23: =CHOOSE($B$4,I38,I50,I62) | ... K23: =CHOOSE($B$4,K38,K50,K62)
A24: NWC / Δ revenue | B24: =CHOOSE($B$4,B39,B51,B63) | C24: =CHOOSE($B$4,C39,C51,C63) | D24: =CHOOSE($B$4,D39,D51,D63) | E24: =CHOOSE($B$4,E39,E51,E63) | F24: =CHOOSE($B$4,F39,F51,F63) | G24: =CHOOSE($B$4,G39,G51,G63) | H24: =CHOOSE($B$4,H39,H51,H63) | I24: =CHOOSE($B$4,I39,I51,I63) | ... K24: =CHOOSE($B$4,K39,K51,K63)
A25: Target FCF margin | B25: =CHOOSE($B$4,B40,B52,B64) | C25: =CHOOSE($B$4,C40,C52,C64) | D25: =CHOOSE($B$4,D40,D52,D64) | E25: =CHOOSE($B$4,E40,E52,E64) | F25: =CHOOSE($B$4,F40,F52,F64) | G25: =CHOOSE($B$4,G40,G52,G64) | H25: =CHOOSE($B$4,H40,H52,H64) | I25: =CHOOSE($B$4,I40,I52,I64) | ... K25: =CHOOSE($B$4,K40,K52,K64)
A31: BEAR CASE ASSUMPTIONS
A32: Assumption | B32: 2026E | C32: 2027E | D32: 2028E | E32: 2029E | F32: 2030E | G32: 2031E | H32: 2032E | I32: 2033E | J32: 2034E | K32: 2035E
A33: Revenue growth | B33: 0.24 | C33: 0.2 | D33: 0.18 | E33: 0.14 | F33: 0.12 | G33: 0.1 | H33: 0.08 | I33: 0.06 | J33: 0.05 | K33: 0.04
A34: Gross margin | B34: 0.47 | C34: 0.465 | D34: 0.46 | E34: 0.458 | F34: 0.456 | G34: 0.454 | H34: 0.452 | I34: 0.45 | J34: 0.45 | K34: 0.45
A35: EBIT margin | B35: 0.16609756 | C35: 0.17195122 | D35: 0.17792683 | E35: 0.18378049 | F35: 0.1897561 | G35: 0.19573171 | H35: 0.20170732 | I35: 0.20158537 | J35: 0.20762195 | K35: 0.21365854
A36: Cash tax rate | B36: 0.18 | C36: 0.18 | D36: 0.18 | E36: 0.18 | F36: 0.18 | G36: 0.18 | H36: 0.18 | I36: 0.18 | J36: 0.18 | K36: 0.18
A37: D&A / revenue | B37: 0.008 | C37: 0.008 | D37: 0.008 | E37: 0.008 | F37: 0.008 | G37: 0.008 | H37: 0.008 | I37: 0.008 | J37: 0.008 | K37: 0.008
A38: CapEx / revenue | B38: 0.003 | C38: 0.003 | D38: 0.003 | E38: 0.003 | F38: 0.003 | G38: 0.003 | H38: 0.003 | I38: 0.003 | J38: 0.003 | K38: 0.003
A39: NWC / Δ revenue | B39: 0.005 | C39: 0.005 | D39: 0.005 | E39: 0.005 | F39: 0.005 | G39: 0.005 | H39: 0.005 | I39: 0.005 | J39: 0.005 | K39: 0.005
A40: Target FCF margin | B40: 0.14 | C40: 0.145 | D40: 0.15 | E40: 0.155 | F40: 0.16 | G40: 0.165 | H40: 0.17 | I40: 0.17 | J40: 0.175 | K40: 0.18
A41: WACC | B41: 0.105
A42: Terminal growth | B42: 0.025
A43: BASE CASE ASSUMPTIONS
A44: Assumption | B44: 2026E | C44: 2027E | D44: 2028E | E44: 2029E | F44: 2030E | G44: 2031E | H44: 2032E | I44: 2033E | J44: 2034E | K44: 2035E
A45: Revenue growth | B45: 0.2805 | C45: 0.238 | D45: 0.252 | E45: 0.2 | F45: 0.17 | G45: 0.14 | H45: 0.11 | I45: 0.09 | J45: 0.07 | K45: 0.05
A46: Gross margin | B46: 0.485 | C46: 0.482 | D46: 0.48 | E46: 0.478 | F46: 0.476 | G46: 0.474 | H46: 0.472 | I46: 0.47 | J46: 0.468 | K46: 0.466
A47: EBIT margin | B47: 0.18988529 | C47: 0.2014 | D47: 0.21324706 | E47: 0.21882353 | F47: 0.22452941 | G47: 0.23023529 | H47: 0.23594118 | I47: 0.24170588 | J47: 0.24747059 | K47: 0.25323529
A48: Cash tax rate | B48: 0.15 | C48: 0.15 | D48: 0.15 | E48: 0.15 | F48: 0.15 | G48: 0.15 | H48: 0.15 | I48: 0.15 | J48: 0.15 | K48: 0.15
A49: D&A / revenue | B49: 0.008 | C49: 0.008 | D49: 0.008 | E49: 0.008 | F49: 0.008 | G49: 0.008 | H49: 0.008 | I49: 0.008 | J49: 0.008 | K49: 0.008
A50: CapEx / revenue | B50: 0.003 | C50: 0.003 | D50: 0.003 | E50: 0.003 | F50: 0.003 | G50: 0.003 | H50: 0.003 | I50: 0.003 | J50: 0.003 | K50: 0.003
...

Sheet Summary
A1: Shopify Inc. DCF Model — Summary
A4: Investment view
A5: Stance | B5: Neutral / Accumulate on pullbacks
A6: Reference price | B6: =DCF!B108
A7: DCF implied value / share | B7: =DCF!B107
A8: DCF upside / downside | B8: =DCF!B109
A9: Street average target | B9: 151.11
A10: Market cap ($M) | B10: 134000
A11: Enterprise value ($M) | B11: 127700
A14: Scenario snapshot
A15: Scenario | B15: WACC | C15: Terminal g | D15: Terminal FCF margin | E15: Implied value / share | F15: Comment
A16: Bear | B16: 0.105 | C16: 0.025 | D16: 0.18 | E16: 47.77 | F16: Growth fade + margin pressure
A17: Base | B17: 0.095 | C17: 0.035 | D17: 0.22 | E17: 96.3 | F17: Consensus fade + 22% terminal FCF margin
A18: Bull | B18: 0.085 | C18: 0.045 | D18: 0.265 | E18: 219.89 | F18: AI/B2B/international upside
A22: Key operating KPIs
A23: KPI | B23: Current | C23: Good | D23: Concern | E23: Source
A24: Revenue growth | B24: Q1 2026 +34% | C24: >25% | D24: <20% | E24: Company/Koyfin
A25: GMV growth | B25: Q1 2026 +35% | C25: >25% | D25: <18% | E25: Company/Koyfin
A26: GPV penetration | B26: 67% | C26: 70–75% path | D26: Stalls <67% | E26: Company notes
A27: FCF margin | B27: Q1 2026 15% | C27: 15–20% | D27: <12% | E27: Company/Koyfin
A28: Gross margin | B28: LTM 48% | C28: Stable 47–49% | D28: <45% | E28: Koyfin

Sheet Revenue Model
A1: Revenue Model
A3: $M | B3: 2022A | C3: 2023A | D3: 2024A | E3: 2025A | F3: 2026E | G3: 2027E | H3: 2028E | I3: 2029E | J3: 2030E | K3: 2031E | L3: 2032E | M3: 2033E | N3: 2034E | O3: 2035E
A4: GMV | B4: 197200 | C4: 235910 | D4: 292275 | E4: 378441 | F4: =F5/0.0305 | G4: =G5/0.03075 | H4: =H5/0.031 | I4: =I5/0.03125 | J4: =J5/0.0315 | K4: =K5/0.03175 | L4: =L5/0.032 | M4: =M5/0.03225 | N4: =N5/0.0325 | O4: =O5/0.03275
A5: Revenue | B5: 5600 | C5: 7060 | D5: 8880 | E5: 11556 | F5: =DCF!F71 | G5: =DCF!G71 | H5: =DCF!H71 | I5: =DCF!I71 | J5: =DCF!J71 | K5: =DCF!K71 | L5: =DCF!L71 | M5: =DCF!M71 | ... O5: =DCF!O71
A6: Take rate | B6: =B5/B4 | C6: =C5/C4 | D6: =D5/D4 | E6: =E5/E4 | F6: =F5/F4 | G6: =G5/G4 | H6: =H5/H4 | I6: =I5/I4 | ... O6: =O5/O4
A8: Subscription Solutions | B8: 1500 | C8: 1800 | D8: 2350 | E8: 2752 | F8: =F5*0.238 | G8: =G5*0.23399999999999999 | H8: =H5*0.22999999999999998 | I8: =I5*0.22599999999999998 | J8: =J5*0.22199999999999998 | K8: =K5*0.218 | L8: =L5*0.214 | M8: =M5*0.21 | N8: =N5*0.206 | O8: =O5*0.20199999999999999
A9: % of revenue | B9: =B8/B5 | C9: =C8/C5 | D9: =D8/D5 | E9: =E8/E5 | F9: =F8/F5 | G9: =G8/G5 | H9: =H8/H5 | I9: =I8/I5 | ... O9: =O8/O5
A10: Merchant Solutions | B10: 4100 | C10: 5200 | D10: 6530 | E10: 8804 | F10: =F5-F8 | G10: =G5-G8 | H10: =H5-H8 | I10: =I5-I8 | J10: =J5-J8 | K10: =K5-K8 | L10: =L5-L8 | M10: =M5-M8 | ... O10: =O5-O8
A11: % of revenue | B11: =B10/B5 | C11: =C10/C5 | D11: =D10/D5 | E11: =E10/E5 | F11: =F10/F5 | G11: =G10/G5 | H11: =H10/H5 | I11: =I10/I5 | ... O11: =O10/O5

Sheet Income Statement
A1: Income Statement
A3: $M | B3: 2022A | C3: 2023A | D3: 2024A | E3: 2025A | F3: 2026E | G3: 2027E | H3: 2028E | I3: 2029E | J3: 2030E | K3: 2031E | L3: 2032E | M3: 2033E | N3: 2034E | O3: 2035E
A4: Revenue | B4: =DCF!B71 | C4: =DCF!C71 | D4: =DCF!D71 | E4: =DCF!E71 | F4: =DCF!F71 | G4: =DCF!G71 | H4: =DCF!H71 | I4: =DCF!I71 | ... O4: =DCF!O71
A5: Gross profit | B5: =DCF!B73 | C5: =DCF!C73 | D5: =DCF!D73 | E5: =DCF!E73 | F5: =DCF!F73 | G5: =DCF!G73 | H5: =DCF!H73 | I5: =DCF!I73 | ... O5: =DCF!O73
A6: Gross margin | B6: =DCF!B74 | C6: =DCF!C74 | D6: =DCF!D74 | E6: =DCF!E74 | F6: =DCF!F74 | G6: =DCF!G74 | H6: =DCF!H74 | I6: =DCF!I74 | ... O6: =DCF!O74
A8: EBIT | B8: =DCF!B75 | C8: =DCF!C75 | D8: =DCF!D75 | E8: =DCF!E75 | F8: =DCF!F75 | G8: =DCF!G75 | H8: =DCF!H75 | I8: =DCF!I75 | ... O8: =DCF!O75
A9: EBIT margin | B9: =DCF!B76 | C9: =DCF!C76 | D9: =DCF!D76 | E9: =DCF!E76 | F9: =DCF!F76 | G9: =DCF!G76 | H9: =DCF!H76 | I9: =DCF!I76 | ... O9: =DCF!O76
A10: Cash taxes | B10: =DCF!B77 | C10: =DCF!C77 | D10: =DCF!D77 | E10: =DCF!E77 | F10: =DCF!F77 | G10: =DCF!G77 | H10: =DCF!H77 | I10: =DCF!I77 | ... O10: =DCF!O77
A11: NOPAT | B11: =DCF!B78 | C11: =DCF!C78 | D11: =DCF!D78 | E11: =DCF!E78 | F11: =DCF!F78 | G11: =DCF!G78 | H11: =DCF!H78 | I11: =DCF!I78 | ... O11: =DCF!O78

Sheet Cash Flow
A1: Cash Flow
A3: $M | B3: 2022A | C3: 2023A | D3: 2024A | E3: 2025A | F3: 2026E | G3: 2027E | H3: 2028E | I3: 2029E | J3: 2030E | K3: 2031E | L3: 2032E | M3: 2033E | N3: 2034E | O3: 2035E
A4: NOPAT | B4: =DCF!B78 | C4: =DCF!C78 | D4: =DCF!D78 | E4: =DCF!E78 | F4: =DCF!F78 | G4: =DCF!G78 | H4: =DCF!H78 | I4: =DCF!I78 | ... O4: =DCF!O78
A5: D&A | B5: =DCF!B79 | C5: =DCF!C79 | D5: =DCF!D79 | E5: =DCF!E79 | F5: =DCF!F79 | G5: =DCF!G79 | H5: =DCF!H79 | I5: =DCF!I79 | ... O5: =DCF!O79
A6: CapEx | B6: =DCF!B80 | C6: =DCF!C80 | D6: =DCF!D80 | E6: =DCF!E80 | F6: =DCF!F80 | G6: =DCF!G80 | H6: =DCF!H80 | I6: =DCF!I80 | ... O6: =DCF!O80
A7: Change in NWC | B7: =DCF!B81 | C7: =DCF!C81 | D7: =DCF!D81 | E7: =DCF!E81 | F7: =DCF!F81 | G7: =DCF!G81 | H7: =DCF!H81 | I7: =DCF!I81 | ... O7: =DCF!O81
A8: Unlevered FCF | B8: =DCF!B82 | C8: =DCF!C82 | D8: =DCF!D82 | E8: =DCF!E82 | F8: =DCF!F82 | G8: =DCF!G82 | H8: =DCF!H82 | I8: =DCF!I82 | ... O8: =DCF!O82
A9: FCF margin | B9: =DCF!B83 | C9: =DCF!C83 | D9: =DCF!D83 | E9: =DCF!E83 | F9: =DCF!F83 | G9: =DCF!G83 | H9: =DCF!H83 | I9: =DCF!I83 | ... O9: =DCF!O83

Sheet Balance Sheet
A1: Balance Sheet
A3: $M | B3: 2022A | C3: 2023A | D3: 2024A | E3: 2025A | F3: 2026E | G3: 2027E | H3: 2028E | I3: 2029E | J3: 2030E | K3: 2031E | L3: 2032E | M3: 2033E | N3: 2034E | O3: 2035E
A4: Cash & investments | E4: 5740 | F4: =E4+MAX(0,DCF!F82*0.25) | G4: =F4+MAX(0,DCF!G82*0.25) | H4: =G4+MAX(0,DCF!H82*0.25) | I4: =H4+MAX(0,DCF!I82*0.25) | J4: =I4+MAX(0,DCF!J82*0.25) | K4: =J4+MAX(0,DCF!K82*0.25) | L4: =K4+MAX(0,DCF!L82*0.25) | M4: =L4+MAX(0,DCF!M82*0.25) | ... O4: =N4+MAX(0,DCF!O82*0.25)
A5: Total debt | E5: 179 | F5: =E5 | G5: =F5 | H5: =G5 | I5: =H5 | J5: =I5 | K5: =J5 | L5: =K5 | M5: =L5 | ... O5: =N5
A6: Net cash | E6: =E4-E5 | F6: =F4-F5 | G6: =G4-G5 | H6: =H4-H5 | I6: =I4-I5 | J6: =J4-J5 | K6: =K4-K5 | L6: =L4-L5 | ... O6: =O4-O5
A8: Shares outstanding (M) | B8: =DCF!$B$9 | C8: =DCF!$B$9 | D8: =DCF!$B$9 | E8: =DCF!$B$9 | F8: =DCF!$B$9 | G8: =DCF!$B$9 | H8: =DCF!$B$9 | I8: =DCF!$B$9 | ... O8: =DCF!$B$9

Sheet Sensitivity
A1: Sensitivity Analysis
A4: WACC vs Terminal Growth
A5: WACC \ Terminal g | B5: 0.025 | C5: 0.03 | D5: 0.035 | E5: 0.04 | F5: 0.045
A6: 0.085 | B6: =(DCF!F82/(1+A6)^0.5+DCF!G82/(1+A6)^1.5+DCF!H82/(1+A6)^2.5+DCF!I82/(1+A6)^3.5+DCF!J82/(1+A6)^4.5+DCF!K82/(1+A6)^5.5+DCF!L82/(1+A6)^6.5+DCF!M82/(1+A6)^7.5+DCF!N82/(1+A6)^8.5+DCF!O82/(1+A6)^9.5+(DCF!O82*(1+B5)/(A6-B5))/(1+A6)^9.5+DCF!$B$10-DCF!$B$11)/DCF!$B$9 | C6: =(DCF!F82/(1+A6)^0.5+DCF!G82/(1+A6)^1.5+DCF!H82/(1+A6)^2.5+DCF!I82/(1+A6)^3.5+DCF!J82/(1+A6)^4.5+DCF!K82/(1+A6)^5.5+DCF!L82/(1+A6)^6.5+DCF!M82/(1+A6)^7.5+DCF!N82/(1+A6)^8.5+DCF!O82/(1+A6)^9.5+(DCF!O82*(1+C5)/(A6-C5))/(1+A6)^9.5+DCF!$B$10-DCF!$B$11)/DCF!$B$9 | D6: =(DCF!F82/(1+A6)^0.5+DCF!G82/(1+A6)^1.5+DCF!H82/(1+A6)^2.5+DCF!I82/(1+A6)^3.5+DCF!J82/(1+A6)^4.5+DCF!K82/(1+A6)^5.5+DCF!L82/(1+A6)^6.5+DCF!M82/(1+A6)^7.5+DCF!N82/(1+A6)^8.5+DCF!O82/(1+A6)^9.5+(DCF!O82*(1+D5)/(A6-D5))/(1+A6)^9.5+DCF!$B$10-DCF!$B$11)/DCF!$B$9 | E6: =(DCF!F82/(1+A6)^0.5+DCF!G82/(1+A6)^1.5+DCF!H82/(1+A6)^2.5+DCF!I82/(1+A6)^3.5+DCF!J82/(1+A6)^4.5+DCF!K82/(1+A6)^5.5+DCF!L82/(1+A6)^6.5+DCF!M82/(1+A6)^7.5+DCF!N82/(1+A6)^8.5+DCF!O82/(1+A6)^9.5+(DCF!O82*(1+E5)/(A6-E5))/(1+A6)^9.5+DCF!$B$10-DCF!$B$11)/DCF!$B$9 | F6: =(DCF!F82/(1+A6)^0.5+DCF!G82/(1+A6)^1.5+DCF!H82/(1+A6)^2.5+DCF!I82/(1+A6)^3.5+DCF!J82/(1+A6)^4.5+DCF!K82/(1+A6)^5.5+DCF!L82/(1+A6)^6.5+DCF!M82/(1+A6)^7.5+DCF!N82/(1+A6)^8.5+DCF!O82/(1+A6)^9.5+(DCF!O82*(1+F5)/(A6-F5))/(1+A6)^9.5+DCF!$B$10-DCF!$B$11)/DCF!$B$9
A7: 0.09 | B7: =(DCF!F82/(1+A7)^0.5+DCF!G82/(1+A7)^1.5+DCF!H82/(1+A7)^2.5+DCF!I82/(1+A7)^3.5+DCF!J82/(1+A7)^4.5+DCF!K82/(1+A7)^5.5+DCF!L82/(1+A7)^6.5+DCF!M82/(1+A7)^7.5+DCF!N82/(1+A7)^8.5+DCF!O82/(1+A7)^9.5+(DCF!O82*(1+B5)/(A7-B5))/(1+A7)^9.5+DCF!$B$10-DCF!$B$11)/DCF!$B$9 | C7: =(DCF!F82/(1+A7)^0.5+DCF!G82/(1+A7)^1.5+DCF!H82/(1+A7)^2.5+DCF!I82/(1+A7)^3.5+DCF!J82/(1+A7)^4.5+DCF!K82/(1+A7)^5.5+DCF!L82/(1+A7)^6.5+DCF!M82/(1+A7)^7.5+DCF!N82/(1+A7)^8.5+DCF!O82/(1+A7)^9.5+(DCF!O82*(1+C5)/(A7-C5))/(1+A7)^9.5+DCF!$B$10-DCF!$B$11)/DCF!$B$9 | D7: =(DCF!F82/(1+A7)^0.5+DCF!G82/(1+A7)^1.5+DCF!H82/(1+A7)^2.5+DCF!I82/(1+A7)^3.5+DCF!J82/(1+A7)^4.5+DCF!K82/(1+A7)^5.5+DCF!L82/(1+A7)^6.5+DCF!M82/(1+A7)^7.5+DCF!N82/(1+A7)^8.5+DCF!O82/(1+A7)^9.5+(DCF!O82*(1+D5)/(A7-D5))/(1+A7)^9.5+DCF!$B$10-DCF!$B$11)/DCF!$B$9 | E7: =(DCF!F82/(1+A7)^0.5+DCF!G82/(1+A7)^1.5+DCF!H82/(1+A7)^2.5+DCF!I82/(1+A7)^3.5+DCF!J82/(1+A7)^4.5+DCF!K82/(1+A7)^5.5+DCF!L82/(1+A7)^6.5+DCF!M82/(1+A7)^7.5+DCF!N82/(1+A7)^8.5+DCF!O82/(1+A7)^9.5+(DCF!O82*(1+E5)/(A7-E5))/(1+A7)^9.5+DCF!$B$10-DCF!$B$11)/DCF!$B$9 | F7: =(DCF!F82/(1+A7)^0.5+DCF!G82/(1+A7)^1.5+DCF!H82/(1+A7)^2.5+DCF!I82/(1+A7)^3.5+DCF!J82/(1+A7)^4.5+DCF!K82/(1+A7)^5.5+DCF!L82/(1+A7)^6.5+DCF!M82/(1+A7)^7.5+DCF!N82/(1+A7)^8.5+DCF!O82/(1+A7)^9.5+(DCF!O82*(1+F5)/(A7-F5))/(1+A7)^9.5+DCF!$B$10-DCF!$B$11)/DCF!$B$9
A8: 0.095 | B8: =(DCF!F82/(1+A8)^0.5+DCF!G82/(1+A8)^1.5+DCF!H82/(1+A8)^2.5+DCF!I82/(1+A8)^3.5+DCF!J82/(1+A8)^4.5+DCF!K82/(1+A8)^5.5+DCF!L82/(1+A8)^6.5+DCF!M82/(1+A8)^7.5+DCF!N82/(1+A8)^8.5+DCF!O82/(1+A8)^9.5+(DCF!O82*(1+B5)/(A8-B5))/(1+A8)^9.5+DCF!$B$10-DCF!$B$11)/DCF!$B$9 | C8: =(DCF!F82/(1+A8)^0.5+DCF!G82/(1+A8)^1.5+DCF!H82/(1+A8)^2.5+DCF!I82/(1+A8)^3.5+DCF!J82/(1+A8)^4.5+DCF!K82/(1+A8)^5.5+DCF!L82/(1+A8)^6.5+DCF!M82/(1+A8)^7.5+DCF!N82/(1+A8)^8.5+DCF!O82/(1+A8)^9.5+(DCF!O82*(1+C5)/(A8-C5))/(1+A8)^9.5+DCF!$B$10-DCF!$B$11)/DCF!$B$9 | D8: =(DCF!F82/(1+A8)^0.5+DCF!G82/(1+A8)^1.5+DCF!H82/(1+A8)^2.5+DCF!I82/(1+A8)^3.5+DCF!J82/(1+A8)^4.5+DCF!K82/(1+A8)^5.5+DCF!L82/(1+A8)^6.5+DCF!M82/(1+A8)^7.5+DCF!N82/(1+A8)^8.5+DCF!O82/(1+A8)^9.5+(DCF!O82*(1+D5)/(A8-D5))/(1+A8)^9.5+DCF!$B$10-DCF!$B$11)/DCF!$B$9 | E8: =(DCF!F82/(1+A8)^0.5+DCF!G82/(1+A8)^1.5+DCF!H82/(1+A8)^2.5+DCF!I82/(1+A8)^3.5+DCF!J82/(1+A8)^4.5+DCF!K82/(1+A8)^5.5+DCF!L82/(1+A8)^6.5+DCF!M82/(1+A8)^7.5+DCF!N82/(1+A8)^8.5+DCF!O82/(1+A8)^9.5+(DCF!O82*(1+E5)/(A8-E5))/(1+A8)^9.5+DCF!$B$10-DCF!$B$11)/DCF!$B$9 | F8: =(DCF!F82/(1+A8)^0.5+DCF!G82/(1+A8)^1.5+DCF!H82/(1+A8)^2.5+DCF!I82/(1+A8)^3.5+DCF!J82/(1+A8)^4.5+DCF!K82/(1+A8)^5.5+DCF!L82/(1+A8)^6.5+DCF!M82/(1+A8)^7.5+DCF!N82/(1+A8)^8.5+DCF!O82/(1+A8)^9.5+(DCF!O82*(1+F5)/(A8-F5))/(1+A8)^9.5+DCF!$B$10-DCF!$B$11)/DCF!$B$9
A9: 0.1 | B9: =(DCF!F82/(1+A9)^0.5+DCF!G82/(1+A9)^1.5+DCF!H82/(1+A9)^2.5+DCF!I82/(1+A9)^3.5+DCF!J82/(1+A9)^4.5+DCF!K82/(1+A9)^5.5+DCF!L82/(1+A9)^6.5+DCF!M82/(1+A9)^7.5+DCF!N82/(1+A9)^8.5+DCF!O82/(1+A9)^9.5+(DCF!O82*(1+B5)/(A9-B5))/(1+A9)^9.5+DCF!$B$10-DCF!$B$11)/DCF!$B$9 | C9: =(DCF!F82/(1+A9)^0.5+DCF!G82/(1+A9)^1.5+DCF!H82/(1+A9)^2.5+DCF!I82/(1+A9)^3.5+DCF!J82/(1+A9)^4.5+DCF!K82/(1+A9)^5.5+DCF!L82/(1+A9)^6.5+DCF!M82/(1+A9)^7.5+DCF!N82/(1+A9)^8.5+DCF!O82/(1+A9)^9.5+(DCF!O82*(1+C5)/(A9-C5))/(1+A9)^9.5+DCF!$B$10-DCF!$B$11)/DCF!$B$9 | D9: =(DCF!F82/(1+A9)^0.5+DCF!G82/(1+A9)^1.5+DCF!H82/(1+A9)^2.5+DCF!I82/(1+A9)^3.5+DCF!J82/(1+A9)^4.5+DCF!K82/(1+A9)^5.5+DCF!L82/(1+A9)^6.5+DCF!M82/(1+A9)^7.5+DCF!N82/(1+A9)^8.5+DCF!O82/(1+A9)^9.5+(DCF!O82*(1+D5)/(A9-D5))/(1+A9)^9.5+DCF!$B$10-DCF!$B$11)/DCF!$B$9 | E9: =(DCF!F82/(1+A9)^0.5+DCF!G82/(1+A9)^1.5+DCF!H82/(1+A9)^2.5+DCF!I82/(1+A9)^3.5+DCF!J82/(1+A9)^4.5+DCF!K82/(1+A9)^5.5+DCF!L82/(1+A9)^6.5+DCF!M82/(1+A9)^7.5+DCF!N82/(1+A9)^8.5+DCF!O82/(1+A9)^9.5+(DCF!O82*(1+E5)/(A9-E5))/(1+A9)^9.5+DCF!$B$10-DCF!$B$11)/DCF!$B$9 | F9: =(DCF!F82/(1+A9)^0.5+DCF!G82/(1+A9)^1.5+DCF!H82/(1+A9)^2.5+DCF!I82/(1+A9)^3.5+DCF!J82/(1+A9)^4.5+DCF!K82/(1+A9)^5.5+DCF!L82/(1+A9)^6.5+DCF!M82/(1+A9)^7.5+DCF!N82/(1+A9)^8.5+DCF!O82/(1+A9)^9.5+(DCF!O82*(1+F5)/(A9-F5))/(1+A9)^9.5+DCF!$B$10-DCF!$B$11)/DCF!$B$9
A10: 0.105 | B10: =(DCF!F82/(1+A10)^0.5+DCF!G82/(1+A10)^1.5+DCF!H82/(1+A10)^2.5+DCF!I82/(1+A10)^3.5+DCF!J82/(1+A10)^4.5+DCF!K82/(1+A10)^5.5+DCF!L82/(1+A10)^6.5+DCF!M82/(1+A10)^7.5+DCF!N82/(1+A10)^8.5+DCF!O82/(1+A10)^9.5+(DCF!O82*(1+B5)/(A10-B5))/(1+A10)^9.5+DCF!$B$10-DCF!$B$11)/DCF!$B$9 | C10: =(DCF!F82/(1+A10)^0.5+DCF!G82/(1+A10)^1.5+DCF!H82/(1+A10)^2.5+DCF!I82/(1+A10)^3.5+DCF!J82/(1+A10)^4.5+DCF!K82/(1+A10)^5.5+DCF!L82/(1+A10)^6.5+DCF!M82/(1+A10)^7.5+DCF!N82/(1+A10)^8.5+DCF!O82/(1+A10)^9.5+(DCF!O82*(1+C5)/(A10-C5))/(1+A10)^9.5+DCF!$B$10-DCF!$B$11)/DCF!$B$9 | D10: =(DCF!F82/(1+A10)^0.5+DCF!G82/(1+A10)^1.5+DCF!H82/(1+A10)^2.5+DCF!I82/(1+A10)^3.5+DCF!J82/(1+A10)^4.5+DCF!K82/(1+A10)^5.5+DCF!L82/(1+A10)^6.5+DCF!M82/(1+A10)^7.5+DCF!N82/(1+A10)^8.5+DCF!O82/(1+A10)^9.5+(DCF!O82*(1+D5)/(A10-D5))/(1+A10)^9.5+DCF!$B$10-DCF!$B$11)/DCF!$B$9 | E10: =(DCF!F82/(1+A10)^0.5+DCF!G82/(1+A10)^1.5+DCF!H82/(1+A10)^2.5+DCF!I82/(1+A10)^3.5+DCF!J82/(1+A10)^4.5+DCF!K82/(1+A10)^5.5+DCF!L82/(1+A10)^6.5+DCF!M82/(1+A10)^7.5+DCF!N82/(1+A10)^8.5+DCF!O82/(1+A10)^9.5+(DCF!O82*(1+E5)/(A10-E5))/(1+A10)^9.5+DCF!$B$10-DCF!$B$11)/DCF!$B$9 | F10: =(DCF!F82/(1+A10)^0.5+DCF!G82/(1+A10)^1.5+DCF!H82/(1+A10)^2.5+DCF!I82/(1+A10)^3.5+DCF!J82/(1+A10)^4.5+DCF!K82/(1+A10)^5.5+DCF!L82/(1+A10)^6.5+DCF!M82/(1+A10)^7.5+DCF!N82/(1+A10)^8.5+DCF!O82/(1+A10)^9.5+(DCF!O82*(1+F5)/(A10-F5))/(1+A10)^9.5+DCF!$B$10-DCF!$B$11)/DCF!$B$9
A14: 2029+ Revenue Growth vs Terminal FCF Margin
A15: 2029+ growth \ Terminal FCF margin | B15: 0.18 | C15: 0.2 | D15: 0.22 | E15: 0.24 | F15: 0.26
A16: 0.06 | B16: =(DCF!F82/(1+DCF!$B$97)^0.5+DCF!G82/(1+DCF!$B$97)^1.5+DCF!H82/(1+DCF!$B$97)^2.5+(DCF!H71*(1+A16)^1)*(18.5%+(B15-18.5%)*1/7)/(1+DCF!$B$97)^3.5+(DCF!H71*(1+A16)^2)*(18.5%+(B15-18.5%)*2/7)/(1+DCF!$B$97)^4.5+(DCF!H71*(1+A16)^3)*(18.5%+(B15-18.5%)*3/7)/(1+DCF!$B$97)^5.5+(DCF!H71*(1+A16)^4)*(18.5%+(B15-18.5%)*4/7)/(1+DCF!$B$97)^6.5+(DCF!H71*(1+A16)^5)*(18.5%+(B15-18.5%)*5/7)/(1+DCF!$B$97)^7.5+(DCF!H71*(1+A16)^6)*(18.5%+(B15-18.5%)*6/7)/(1+DCF!$B$97)^8.5+(DCF!H71*(1+A16)^7)*(18.5%+(B15-18.5%)*7/7)/(1+DCF!$B$97)^9.5+((DCF!H71*(1+A16)^7)*(18.5%+(B15-18.5%)*7/7)*(1+DCF!$B$98)/(DCF!$B$97-DCF!$B$98))/(1+DCF!$B$97)^9.5+DCF!$B$10-DCF!$B$11)/DCF!$B$9 | C16: =(DCF!F82/(1+DCF!$B$97)^0.5+DCF!G82/(1+DCF!$B$97)^1.5+DCF!H82/(1+DCF!$B$97)^2.5+(DCF!H71*(1+A16)^1)*(18.5%+(C15-18.5%)*1/7)/(1+DCF!$B$97)^3.5+(DCF!H71*(1+A16)^2)*(18.5%+(C15-18.5%)*2/7)/(1+DCF!$B$97)^4.5+(DCF!H71*(1+A16)^3)*(18.5%+(C15-18.5%)*3/7)/(1+DCF!$B$97)^5.5+(DCF!H71*(1+A16)^4)*(18.5%+(C15-18.5%)*4/7)/(1+DCF!$B$97)^6.5+(DCF!H71*(1+A16)^5)*(18.5%+(C15-18.5%)*5/7)/(1+DCF!$B$97)^7.5+(DCF!H71*(1+A16)^6)*(18.5%+(C15-18.5%)*6/7)/(1+DCF!$B$97)^8.5+(DCF!H71*(1+A16)^7)*(18.5%+(C15-18.5%)*7/7)/(1+DCF!$B$97)^9.5+((DCF!H71*(1+A16)^7)*(18.5%+(C15-18.5%)*7/7)*(1+DCF!$B$98)/(DCF!$B$97-DCF!$B$98))/(1+DCF!$B$97)^9.5+DCF!$B$10-DCF!$B$11)/DCF!$B$9 | D16: =(DCF!F82/(1+DCF!$B$97)^0.5+DCF!G82/(1+DCF!$B$97)^1.5+DCF!H82/(1+DCF!$B$97)^2.5+(DCF!H71*(1+A16)^1)*(18.5%+(D15-18.5%)*1/7)/(1+DCF!$B$97)^3.5+(DCF!H71*(1+A16)^2)*(18.5%+(D15-18.5%)*2/7)/(1+DCF!$B$97)^4.5+(DCF!H71*(1+A16)^3)*(18.5%+(D15-18.5%)*3/7)/(1+DCF!$B$97)^5.5+(DCF!H71*(1+A16)^4)*(18.5%+(D15-18.5%)*4/7)/(1+DCF!$B$97)^6.5+(DCF!H71*(1+A16)^5)*(18.5%+(D15-18.5%)*5/7)/(1+DCF!$B$97)^7.5+(DCF!H71*(1+A16)^6)*(18.5%+(D15-18.5%)*6/7)/(1+DCF!$B$97)^8.5+(DCF!H71*(1+A16)^7)*(18.5%+(D15-18.5%)*7/7)/(1+DCF!$B$97)^9.5+((DCF!H71*(1+A16)^7)*(18.5%+(D15-18.5%)*7/7)*(1+DCF!$B$98)/(DCF!$B$97-DCF!$B$98))/(1+DCF!$B$97)^9.5+DCF!$B$10-DCF!$B$11)/DCF!$B$9 | E16: =(DCF!F82/(1+DCF!$B$97)^0.5+DCF!G82/(1+DCF!$B$97)^1.5+DCF!H82/(1+DCF!$B$97)^2.5+(DCF!H71*(1+A16)^1)*(18.5%+(E15-18.5%)*1/7)/(1+DCF!$B$97)^3.5+(DCF!H71*(1+A16)^2)*(18.5%+(E15-18.5%)*2/7)/(1+DCF!$B$97)^4.5+(DCF!H71*(1+A16)^3)*(18.5%+(E15-18.5%)*3/7)/(1+DCF!$B$97)^5.5+(DCF!H71*(1+A16)^4)*(18.5%+(E15-18.5%)*4/7)/(1+DCF!$B$97)^6.5+(DCF!H71*(1+A16)^5)*(18.5%+(E15-18.5%)*5/7)/(1+DCF!$B$97)^7.5+(DCF!H71*(1+A16)^6)*(18.5%+(E15-18.5%)*6/7)/(1+DCF!$B$97)^8.5+(DCF!H71*(1+A16)^7)*(18.5%+(E15-18.5%)*7/7)/(1+DCF!$B$97)^9.5+((DCF!H71*(1+A16)^7)*(18.5%+(E15-18.5%)*7/7)*(1+DCF!$B$98)/(DCF!$B$97-DCF!$B$98))/(1+DCF!$B$97)^9.5+DCF!$B$10-DCF!$B$11)/DCF!$B$9 | F16: =(DCF!F82/(1+DCF!$B$97)^0.5+DCF!G82/(1+DCF!$B$97)^1.5+DCF!H82/(1+DCF!$B$97)^2.5+(DCF!H71*(1+A16)^1)*(18.5%+(F15-18.5%)*1/7)/(1+DCF!$B$97)^3.5+(DCF!H71*(1+A16)^2)*(18.5%+(F15-18.5%)*2/7)/(1+DCF!$B$97)^4.5+(DCF!H71*(1+A16)^3)*(18.5%+(F15-18.5%)*3/7)/(1+DCF!$B$97)^5.5+(DCF!H71*(1+A16)^4)*(18.5%+(F15-18.5%)*4/7)/(1+DCF!$B$97)^6.5+(DCF!H71*(1+A16)^5)*(18.5%+(F15-18.5%)*5/7)/(1+DCF!$B$97)^7.5+(DCF!H71*(1+A16)^6)*(18.5%+(F15-18.5%)*6/7)/(1+DCF!$B$97)^8.5+(DCF!H71*(1+A16)^7)*(18.5%+(F15-18.5%)*7/7)/(1+DCF!$B$97)^9.5+((DCF!H71*(1+A16)^7)*(18.5%+(F15-18.5%)*7/7)*(1+DCF!$B$98)/(DCF!$B$97-DCF!$B$98))/(1+DCF!$B$97)^9.5+DCF!$B$10-DCF!$B$11)/DCF!$B$9
A17: 0.08 | B17: =(DCF!F82/(1+DCF!$B$97)^0.5+DCF!G82/(1+DCF!$B$97)^1.5+DCF!H82/(1+DCF!$B$97)^2.5+(DCF!H71*(1+A17)^1)*(18.5%+(B15-18.5%)*1/7)/(1+DCF!$B$97)^3.5+(DCF!H71*(1+A17)^2)*(18.5%+(B15-18.5%)*2/7)/(1+DCF!$B$97)^4.5+(DCF!H71*(1+A17)^3)*(18.5%+(B15-18.5%)*3/7)/(1+DCF!$B$97)^5.5+(DCF!H71*(1+A17)^4)*(18.5%+(B15-18.5%)*4/7)/(1+DCF!$B$97)^6.5+(DCF!H71*(1+A17)^5)*(18.5%+(B15-18.5%)*5/7)/(1+DCF!$B$97)^7.5+(DCF!H71*(1+A17)^6)*(18.5%+(B15-18.5%)*6/7)/(1+DCF!$B$97)^8.5+(DCF!H71*(1+A17)^7)*(18.5%+(B15-18.5%)*7/7)/(1+DCF!$B$97)^9.5+((DCF!H71*(1+A17)^7)*(18.5%+(B15-18.5%)*7/7)*(1+DCF!$B$98)/(DCF!$B$97-DCF!$B$98))/(1+DCF!$B$97)^9.5+DCF!$B$10-DCF!$B$11)/DCF!$B$9 | C17: =(DCF!F82/(1+DCF!$B$97)^0.5+DCF!G82/(1+DCF!$B$97)^1.5+DCF!H82/(1+DCF!$B$97)^2.5+(DCF!H71*(1+A17)^1)*(18.5%+(C15-18.5%)*1/7)/(1+DCF!$B$97)^3.5+(DCF!H71*(1+A17)^2)*(18.5%+(C15-18.5%)*2/7)/(1+DCF!$B$97)^4.5+(DCF!H71*(1+A17)^3)*(18.5%+(C15-18.5%)*3/7)/(1+DCF!$B$97)^5.5+(DCF!H71*(1+A17)^4)*(18.5%+(C15-18.5%)*4/7)/(1+DCF!$B$97)^6.5+(DCF!H71*(1+A17)^5)*(18.5%+(C15-18.5%)*5/7)/(1+DCF!$B$97)^7.5+(DCF!H71*(1+A17)^6)*(18.5%+(C15-18.5%)*6/7)/(1+DCF!$B$97)^8.5+(DCF!H71*(1+A17)^7)*(18.5%+(C15-18.5%)*7/7)/(1+DCF!$B$97)^9.5+((DCF!H71*(1+A17)^7)*(18.5%+(C15-18.5%)*7/7)*(1+DCF!$B$98)/(DCF!$B$97-DCF!$B$98))/(1+DCF!$B$97)^9.5+DCF!$B$10-DCF!$B$11)/DCF!$B$9 | D17: =(DCF!F82/(1+DCF!$B$97)^0.5+DCF!G82/(1+DCF!$B$97)^1.5+DCF!H82/(1+DCF!$B$97)^2.5+(DCF!H71*(1+A17)^1)*(18.5%+(D15-18.5%)*1/7)/(1+DCF!$B$97)^3.5+(DCF!H71*(1+A17)^2)*(18.5%+(D15-18.5%)*2/7)/(1+DCF!$B$97)^4.5+(DCF!H71*(1+A17)^3)*(18.5%+(D15-18.5%)*3/7)/(1+DCF!$B$97)^5.5+(DCF!H71*(1+A17)^4)*(18.5%+(D15-18.5%)*4/7)/(1+DCF!$B$97)^6.5+(DCF!H71*(1+A17)^5)*(18.5%+(D15-18.5%)*5/7)/(1+DCF!$B$97)^7.5+(DCF!H71*(1+A17)^6)*(18.5%+(D15-18.5%)*6/7)/(1+DCF!$B$97)^8.5+(DCF!H71*(1+A17)^7)*(18.5%+(D15-18.5%)*7/7)/(1+DCF!$B$97)^9.5+((DCF!H71*(1+A17)^7)*(18.5%+(D15-18.5%)*7/7)*(1+DCF!$B$98)/(DCF!$B$97-DCF!$B$98))/(1+DCF!$B$97)^9.5+DCF!$B$10-DCF!$B$11)/DCF!$B$9 | E17: =(DCF!F82/(1+DCF!$B$97)^0.5+DCF!G82/(1+DCF!$B$97)^1.5+DCF!H82/(1+DCF!$B$97)^2.5+(DCF!H71*(1+A17)^1)*(18.5%+(E15-18.5%)*1/7)/(1+DCF!$B$97)^3.5+(DCF!H71*(1+A17)^2)*(18.5%+(E15-18.5%)*2/7)/(1+DCF!$B$97)^4.5+(DCF!H71*(1+A17)^3)*(18.5%+(E15-18.5%)*3/7)/(1+DCF!$B$97)^5.5+(DCF!H71*(1+A17)^4)*(18.5%+(E15-18.5%)*4/7)/(1+DCF!$B$97)^6.5+(DCF!H71*(1+A17)^5)*(18.5%+(E15-18.5%)*5/7)/(1+DCF!$B$97)^7.5+(DCF!H71*(1+A17)^6)*(18.5%+(E15-18.5%)*6/7)/(1+DCF!$B$97)^8.5+(DCF!H71*(1+A17)^7)*(18.5%+(E15-18.5%)*7/7)/(1+DCF!$B$97)^9.5+((DCF!H71*(1+A17)^7)*(18.5%+(E15-18.5%)*7/7)*(1+DCF!$B$98)/(DCF!$B$97-DCF!$B$98))/(1+DCF!$B$97)^9.5+DCF!$B$10-DCF!$B$11)/DCF!$B$9 | F17: =(DCF!F82/(1+DCF!$B$97)^0.5+DCF!G82/(1+DCF!$B$97)^1.5+DCF!H82/(1+DCF!$B$97)^2.5+(DCF!H71*(1+A17)^1)*(18.5%+(F15-18.5%)*1/7)/(1+DCF!$B$97)^3.5+(DCF!H71*(1+A17)^2)*(18.5%+(F15-18.5%)*2/7)/(1+DCF!$B$97)^4.5+(DCF!H71*(1+A17)^3)*(18.5%+(F15-18.5%)*3/7)/(1+DCF!$B$97)^5.5+(DCF!H71*(1+A17)^4)*(18.5%+(F15-18.5%)*4/7)/(1+DCF!$B$97)^6.5+(DCF!H71*(1+A17)^5)*(18.5%+(F15-18.5%)*5/7)/(1+DCF!$B$97)^7.5+(DCF!H71*(1+A17)^6)*(18.5%+(F15-18.5%)*6/7)/(1+DCF!$B$97)^8.5+(DCF!H71*(1+A17)^7)*(18.5%+(F15-18.5%)*7/7)/(1+DCF!$B$97)^9.5+((DCF!H71*(1+A17)^7)*(18.5%+(F15-18.5%)*7/7)*(1+DCF!$B$98)/(DCF!$B$97-DCF!$B$98))/(1+DCF!$B$97)^9.5+DCF!$B$10-DCF!$B$11)/DCF!$B$9
A18: 0.1 | B18: =(DCF!F82/(1+DCF!$B$97)^0.5+DCF!G82/(1+DCF!$B$97)^1.5+DCF!H82/(1+DCF!$B$97)^2.5+(DCF!H71*(1+A18)^1)*(18.5%+(B15-18.5%)*1/7)/(1+DCF!$B$97)^3.5+(DCF!H71*(1+A18)^2)*(18.5%+(B15-18.5%)*2/7)/(1+DCF!$B$97)^4.5+(DCF!H71*(1+A18)^3)*(18.5%+(B15-18.5%)*3/7)/(1+DCF!$B$97)^5.5+(DCF!H71*(1+A18)^4)*(18.5%+(B15-18.5%)*4/7)/(1+DCF!$B$97)^6.5+(DCF!H71*(1+A18)^5)*(18.5%+(B15-18.5%)*5/7)/(1+DCF!$B$97)^7.5+(DCF!H71*(1+A18)^6)*(18.5%+(B15-18.5%)*6/7)/(1+DCF!$B$97)^8.5+(DCF!H71*(1+A18)^7)*(18.5%+(B15-18.5%)*7/7)/(1+DCF!$B$97)^9.5+((DCF!H71*(1+A18)^7)*(18.5%+(B15-18.5%)*7/7)*(1+DCF!$B$98)/(DCF!$B$97-DCF!$B$98))/(1+DCF!$B$97)^9.5+DCF!$B$10-DCF!$B$11)/DCF!$B$9 | C18: =(DCF!F82/(1+DCF!$B$97)^0.5+DCF!G82/(1+DCF!$B$97)^1.5+DCF!H82/(1+DCF!$B$97)^2.5+(DCF!H71*(1+A18)^1)*(18.5%+(C15-18.5%)*1/7)/(1+DCF!$B$97)^3.5+(DCF!H71*(1+A18)^2)*(18.5%+(C15-18.5%)*2/7)/(1+DCF!$B$97)^4.5+(DCF!H71*(1+A18)^3)*(18.5%+(C15-18.5%)*3/7)/(1+DCF!$B$97)^5.5+(DCF!H71*(1+A18)^4)*(18.5%+(C15-18.5%)*4/7)/(1+DCF!$B$97)^6.5+(DCF!H71*(1+A18)^5)*(18.5%+(C15-18.5%)*5/7)/(1+DCF!$B$97)^7.5+(DCF!H71*(1+A18)^6)*(18.5%+(C15-18.5%)*6/7)/(1+DCF!$B$97)^8.5+(DCF!H71*(1+A18)^7)*(18.5%+(C15-18.5%)*7/7)/(1+DCF!$B$97)^9.5+((DCF!H71*(1+A18)^7)*(18.5%+(C15-18.5%)*7/7)*(1+DCF!$B$98)/(DCF!$B$97-DCF!$B$98))/(1+DCF!$B$97)^9.5+DCF!$B$10-DCF!$B$11)/DCF!$B$9 | D18: =(DCF!F82/(1+DCF!$B$97)^0.5+DCF!G82/(1+DCF!$B$97)^1.5+DCF!H82/(1+DCF!$B$97)^2.5+(DCF!H71*(1+A18)^1)*(18.5%+(D15-18.5%)*1/7)/(1+DCF!$B$97)^3.5+(DCF!H71*(1+A18)^2)*(18.5%+(D15-18.5%)*2/7)/(1+DCF!$B$97)^4.5+(DCF!H71*(1+A18)^3)*(18.5%+(D15-18.5%)*3/7)/(1+DCF!$B$97)^5.5+(DCF!H71*(1+A18)^4)*(18.5%+(D15-18.5%)*4/7)/(1+DCF!$B$97)^6.5+(DCF!H71*(1+A18)^5)*(18.5%+(D15-18.5%)*5/7)/(1+DCF!$B$97)^7.5+(DCF!H71*(1+A18)^6)*(18.5%+(D15-18.5%)*6/7)/(1+DCF!$B$97)^8.5+(DCF!H71*(1+A18)^7)*(18.5%+(D15-18.5%)*7/7)/(1+DCF!$B$97)^9.5+((DCF!H71*(1+A18)^7)*(18.5%+(D15-18.5%)*7/7)*(1+DCF!$B$98)/(DCF!$B$97-DCF!$B$98))/(1+DCF!$B$97)^9.5+DCF!$B$10-DCF!$B$11)/DCF!$B$9 | E18: =(DCF!F82/(1+DCF!$B$97)^0.5+DCF!G82/(1+DCF!$B$97)^1.5+DCF!H82/(1+DCF!$B$97)^2.5+(DCF!H71*(1+A18)^1)*(18.5%+(E15-18.5%)*1/7)/(1+DCF!$B$97)^3.5+(DCF!H71*(1+A18)^2)*(18.5%+(E15-18.5%)*2/7)/(1+DCF!$B$97)^4.5+(DCF!H71*(1+A18)^3)*(18.5%+(E15-18.5%)*3/7)/(1+DCF!$B$97)^5.5+(DCF!H71*(1+A18)^4)*(18.5%+(E15-18.5%)*4/7)/(1+DCF!$B$97)^6.5+(DCF!H71*(1+A18)^5)*(18.5%+(E15-18.5%)*5/7)/(1+DCF!$B$97)^7.5+(DCF!H71*(1+A18)^6)*(18.5%+(E15-18.5%)*6/7)/(1+DCF!$B$97)^8.5+(DCF!H71*(1+A18)^7)*(18.5%+(E15-18.5%)*7/7)/(1+DCF!$B$97)^9.5+((DCF!H71*(1+A18)^7)*(18.5%+(E15-18.5%)*7/7)*(1+DCF!$B$98)/(DCF!$B$97-DCF!$B$98))/(1+DCF!$B$97)^9.5+DCF!$B$10-DCF!$B$11)/DCF!$B$9 | F18: =(DCF!F82/(1+DCF!$B$97)^0.5+DCF!G82/(1+DCF!$B$97)^1.5+DCF!H82/(1+DCF!$B$97)^2.5+(DCF!H71*(1+A18)^1)*(18.5%+(F15-18.5%)*1/7)/(1+DCF!$B$97)^3.5+(DCF!H71*(1+A18)^2)*(18.5%+(F15-18.5%)*2/7)/(1+DCF!$B$97)^4.5+(DCF!H71*(1+A18)^3)*(18.5%+(F15-18.5%)*3/7)/(1+DCF!$B$97)^5.5+(DCF!H71*(1+A18)^4)*(18.5%+(F15-18.5%)*4/7)/(1+DCF!$B$97)^6.5+(DCF!H71*(1+A18)^5)*(18.5%+(F15-18.5%)*5/7)/(1+DCF!$B$97)^7.5+(DCF!H71*(1+A18)^6)*(18.5%+(F15-18.5%)*6/7)/(1+DCF!$B$97)^8.5+(DCF!H71*(1+A18)^7)*(18.5%+(F15-18.5%)*7/7)/(1+DCF!$B$97)^9.5+((DCF!H71*(1+A18)^7)*(18.5%+(F15-18.5%)*7/7)*(1+DCF!$B$98)/(DCF!$B$97-DCF!$B$98))/(1+DCF!$B$97)^9.5+DCF!$B$10-DCF!$B$11)/DCF!$B$9
A19: 0.12 | B19: =(DCF!F82/(1+DCF!$B$97)^0.5+DCF!G82/(1+DCF!$B$97)^1.5+DCF!H82/(1+DCF!$B$97)^2.5+(DCF!H71*(1+A19)^1)*(18.5%+(B15-18.5%)*1/7)/(1+DCF!$B$97)^3.5+(DCF!H71*(1+A19)^2)*(18.5%+(B15-18.5%)*2/7)/(1+DCF!$B$97)^4.5+(DCF!H71*(1+A19)^3)*(18.5%+(B15-18.5%)*3/7)/(1+DCF!$B$97)^5.5+(DCF!H71*(1+A19)^4)*(18.5%+(B15-18.5%)*4/7)/(1+DCF!$B$97)^6.5+(DCF!H71*(1+A19)^5)*(18.5%+(B15-18.5%)*5/7)/(1+DCF!$B$97)^7.5+(DCF!H71*(1+A19)^6)*(18.5%+(B15-18.5%)*6/7)/(1+DCF!$B$97)^8.5+(DCF!H71*(1+A19)^7)*(18.5%+(B15-18.5%)*7/7)/(1+DCF!$B$97)^9.5+((DCF!H71*(1+A19)^7)*(18.5%+(B15-18.5%)*7/7)*(1+DCF!$B$98)/(DCF!$B$97-DCF!$B$98))/(1+DCF!$B$97)^9.5+DCF!$B$10-DCF!$B$11)/DCF!$B$9 | C19: =(DCF!F82/(1+DCF!$B$97)^0.5+DCF!G82/(1+DCF!$B$97)^1.5+DCF!H82/(1+DCF!$B$97)^2.5+(DCF!H71*(1+A19)^1)*(18.5%+(C15-18.5%)*1/7)/(1+DCF!$B$97)^3.5+(DCF!H71*(1+A19)^2)*(18.5%+(C15-18.5%)*2/7)/(1+DCF!$B$97)^4.5+(DCF!H71*(1+A19)^3)*(18.5%+(C15-18.5%)*3/7)/(1+DCF!$B$97)^5.5+(DCF!H71*(1+A19)^4)*(18.5%+(C15-18.5%)*4/7)/(1+DCF!$B$97)^6.5+(DCF!H71*(1+A19)^5)*(18.5%+(C15-18.5%)*5/7)/(1+DCF!$B$97)^7.5+(DCF!H71*(1+A19)^6)*(18.5%+(C15-18.5%)*6/7)/(1+DCF!$B$97)^8.5+(DCF!H71*(1+A19)^7)*(18.5%+(C15-18.5%)*7/7)/(1+DCF!$B$97)^9.5+((DCF!H71*(1+A19)^7)*(18.5%+(C15-18.5%)*7/7)*(1+DCF!$B$98)/(DCF!$B$97-DCF!$B$98))/(1+DCF!$B$97)^9.5+DCF!$B$10-DCF!$B$11)/DCF!$B$9 | D19: =(DCF!F82/(1+DCF!$B$97)^0.5+DCF!G82/(1+DCF!$B$97)^1.5+DCF!H82/(1+DCF!$B$97)^2.5+(DCF!H71*(1+A19)^1)*(18.5%+(D15-18.5%)*1/7)/(1+DCF!$B$97)^3.5+(DCF!H71*(1+A19)^2)*(18.5%+(D15-18.5%)*2/7)/(1+DCF!$B$97)^4.5+(DCF!H71*(1+A19)^3)*(18.5%+(D15-18.5%)*3/7)/(1+DCF!$B$97)^5.5+(DCF!H71*(1+A19)^4)*(18.5%+(D15-18.5%)*4/7)/(1+DCF!$B$97)^6.5+(DCF!H71*(1+A19)^5)*(18.5%+(D15-18.5%)*5/7)/(1+DCF!$B$97)^7.5+(DCF!H71*(1+A19)^6)*(18.5%+(D15-18.5%)*6/7)/(1+DCF!$B$97)^8.5+(DCF!H71*(1+A19)^7)*(18.5%+(D15-18.5%)*7/7)/(1+DCF!$B$97)^9.5+((DCF!H71*(1+A19)^7)*(18.5%+(D15-18.5%)*7/7)*(1+DCF!$B$98)/(DCF!$B$97-DCF!$B$98))/(1+DCF!$B$97)^9.5+DCF!$B$10-DCF!$B$11)/DCF!$B$9 | E19: =(DCF!F82/(1+DCF!$B$97)^0.5+DCF!G82/(1+DCF!$B$97)^1.5+DCF!H82/(1+DCF!$B$97)^2.5+(DCF!H71*(1+A19)^1)*(18.5%+(E15-18.5%)*1/7)/(1+DCF!$B$97)^3.5+(DCF!H71*(1+A19)^2)*(18.5%+(E15-18.5%)*2/7)/(1+DCF!$B$97)^4.5+(DCF!H71*(1+A19)^3)*(18.5%+(E15-18.5%)*3/7)/(1+DCF!$B$97)^5.5+(DCF!H71*(1+A19)^4)*(18.5%+(E15-18.5%)*4/7)/(1+DCF!$B$97)^6.5+(DCF!H71*(1+A19)^5)*(18.5%+(E15-18.5%)*5/7)/(1+DCF!$B$97)^7.5+(DCF!H71*(1+A19)^6)*(18.5%+(E15-18.5%)*6/7)/(1+DCF!$B$97)^8.5+(DCF!H71*(1+A19)^7)*(18.5%+(E15-18.5%)*7/7)/(1+DCF!$B$97)^9.5+((DCF!H71*(1+A19)^7)*(18.5%+(E15-18.5%)*7/7)*(1+DCF!$B$98)/(DCF!$B$97-DCF!$B$98))/(1+DCF!$B$97)^9.5+DCF!$B$10-DCF!$B$11)/DCF!$B$9 | F19: =(DCF!F82/(1+DCF!$B$97)^0.5+DCF!G82/(1+DCF!$B$97)^1.5+DCF!H82/(1+DCF!$B$97)^2.5+(DCF!H71*(1+A19)^1)*(18.5%+(F15-18.5%)*1/7)/(1+DCF!$B$97)^3.5+(DCF!H71*(1+A19)^2)*(18.5%+(F15-18.5%)*2/7)/(1+DCF!$B$97)^4.5+(DCF!H71*(1+A19)^3)*(18.5%+(F15-18.5%)*3/7)/(1+DCF!$B$97)^5.5+(DCF!H71*(1+A19)^4)*(18.5%+(F15-18.5%)*4/7)/(1+DCF!$B$97)^6.5+(DCF!H71*(1+A19)^5)*(18.5%+(F15-18.5%)*5/7)/(1+DCF!$B$97)^7.5+(DCF!H71*(1+A19)^6)*(18.5%+(F15-18.5%)*6/7)/(1+DCF!$B$97)^8.5+(DCF!H71*(1+A19)^7)*(18.5%+(F15-18.5%)*7/7)/(1+DCF!$B$97)^9.5+((DCF!H71*(1+A19)^7)*(18.5%+(F15-18.5%)*7/7)*(1+DCF!$B$98)/(DCF!$B$97-DCF!$B$98))/(1+DCF!$B$97)^9.5+DCF!$B$10-DCF!$B$11)/DCF!$B$9
A20: 0.14 | B20: =(DCF!F82/(1+DCF!$B$97)^0.5+DCF!G82/(1+DCF!$B$97)^1.5+DCF!H82/(1+DCF!$B$97)^2.5+(DCF!H71*(1+A20)^1)*(18.5%+(B15-18.5%)*1/7)/(1+DCF!$B$97)^3.5+(DCF!H71*(1+A20)^2)*(18.5%+(B15-18.5%)*2/7)/(1+DCF!$B$97)^4.5+(DCF!H71*(1+A20)^3)*(18.5%+(B15-18.5%)*3/7)/(1+DCF!$B$97)^5.5+(DCF!H71*(1+A20)^4)*(18.5%+(B15-18.5%)*4/7)/(1+DCF!$B$97)^6.5+(DCF!H71*(1+A20)^5)*(18.5%+(B15-18.5%)*5/7)/(1+DCF!$B$97)^7.5+(DCF!H71*(1+A20)^6)*(18.5%+(B15-18.5%)*6/7)/(1+DCF!$B$97)^8.5+(DCF!H71*(1+A20)^7)*(18.5%+(B15-18.5%)*7/7)/(1+DCF!$B$97)^9.5+((DCF!H71*(1+A20)^7)*(18.5%+(B15-18.5%)*7/7)*(1+DCF!$B$98)/(DCF!$B$97-DCF!$B$98))/(1+DCF!$B$97)^9.5+DCF!$B$10-DCF!$B$11)/DCF!$B$9 | C20: =(DCF!F82/(1+DCF!$B$97)^0.5+DCF!G82/(1+DCF!$B$97)^1.5+DCF!H82/(1+DCF!$B$97)^2.5+(DCF!H71*(1+A20)^1)*(18.5%+(C15-18.5%)*1/7)/(1+DCF!$B$97)^3.5+(DCF!H71*(1+A20)^2)*(18.5%+(C15-18.5%)*2/7)/(1+DCF!$B$97)^4.5+(DCF!H71*(1+A20)^3)*(18.5%+(C15-18.5%)*3/7)/(1+DCF!$B$97)^5.5+(DCF!H71*(1+A20)^4)*(18.5%+(C15-18.5%)*4/7)/(1+DCF!$B$97)^6.5+(DCF!H71*(1+A20)^5)*(18.5%+(C15-18.5%)*5/7)/(1+DCF!$B$97)^7.5+(DCF!H71*(1+A20)^6)*(18.5%+(C15-18.5%)*6/7)/(1+DCF!$B$97)^8.5+(DCF!H71*(1+A20)^7)*(18.5%+(C15-18.5%)*7/7)/(1+DCF!$B$97)^9.5+((DCF!H71*(1+A20)^7)*(18.5%+(C15-18.5%)*7/7)*(1+DCF!$B$98)/(DCF!$B$97-DCF!$B$98))/(1+DCF!$B$97)^9.5+DCF!$B$10-DCF!$B$11)/DCF!$B$9 | D20: =(DCF!F82/(1+DCF!$B$97)^0.5+DCF!G82/(1+DCF!$B$97)^1.5+DCF!H82/(1+DCF!$B$97)^2.5+(DCF!H71*(1+A20)^1)*(18.5%+(D15-18.5%)*1/7)/(1+DCF!$B$97)^3.5+(DCF!H71*(1+A20)^2)*(18.5%+(D15-18.5%)*2/7)/(1+DCF!$B$97)^4.5+(DCF!H71*(1+A20)^3)*(18.5%+(D15-18.5%)*3/7)/(1+DCF!$B$97)^5.5+(DCF!H71*(1+A20)^4)*(18.5%+(D15-18.5%)*4/7)/(1+DCF!$B$97)^6.5+(DCF!H71*(1+A20)^5)*(18.5%+(D15-18.5%)*5/7)/(1+DCF!$B$97)^7.5+(DCF!H71*(1+A20)^6)*(18.5%+(D15-18.5%)*6/7)/(1+DCF!$B$97)^8.5+(DCF!H71*(1+A20)^7)*(18.5%+(D15-18.5%)*7/7)/(1+DCF!$B$97)^9.5+((DCF!H71*(1+A20)^7)*(18.5%+(D15-18.5%)*7/7)*(1+DCF!$B$98)/(DCF!$B$97-DCF!$B$98))/(1+DCF!$B$97)^9.5+DCF!$B$10-DCF!$B$11)/DCF!$B$9 | E20: =(DCF!F82/(1+DCF!$B$97)^0.5+DCF!G82/(1+DCF!$B$97)^1.5+DCF!H82/(1+DCF!$B$97)^2.5+(DCF!H71*(1+A20)^1)*(18.5%+(E15-18.5%)*1/7)/(1+DCF!$B$97)^3.5+(DCF!H71*(1+A20)^2)*(18.5%+(E15-18.5%)*2/7)/(1+DCF!$B$97)^4.5+(DCF!H71*(1+A20)^3)*(18.5%+(E15-18.5%)*3/7)/(1+DCF!$B$97)^5.5+(DCF!H71*(1+A20)^4)*(18.5%+(E15-18.5%)*4/7)/(1+DCF!$B$97)^6.5+(DCF!H71*(1+A20)^5)*(18.5%+(E15-18.5%)*5/7)/(1+DCF!$B$97)^7.5+(DCF!H71*(1+A20)^6)*(18.5%+(E15-18.5%)*6/7)/(1+DCF!$B$97)^8.5+(DCF!H71*(1+A20)^7)*(18.5%+(E15-18.5%)*7/7)/(1+DCF!$B$97)^9.5+((DCF!H71*(1+A20)^7)*(18.5%+(E15-18.5%)*7/7)*(1+DCF!$B$98)/(DCF!$B$97-DCF!$B$98))/(1+DCF!$B$97)^9.5+DCF!$B$10-DCF!$B$11)/DCF!$B$9 | F20: =(DCF!F82/(1+DCF!$B$97)^0.5+DCF!G82/(1+DCF!$B$97)^1.5+DCF!H82/(1+DCF!$B$97)^2.5+(DCF!H71*(1+A20)^1)*(18.5%+(F15-18.5%)*1/7)/(1+DCF!$B$97)^3.5+(DCF!H71*(1+A20)^2)*(18.5%+(F15-18.5%)*2/7)/(1+DCF!$B$97)^4.5+(DCF!H71*(1+A20)^3)*(18.5%+(F15-18.5%)*3/7)/(1+DCF!$B$97)^5.5+(DCF!H71*(1+A20)^4)*(18.5%+(F15-18.5%)*4/7)/(1+DCF!$B$97)^6.5+(DCF!H71*(1+A20)^5)*(18.5%+(F15-18.5%)*5/7)/(1+DCF!$B$97)^7.5+(DCF!H71*(1+A20)^6)*(18.5%+(F15-18.5%)*6/7)/(1+DCF!$B$97)^8.5+(DCF!H71*(1+A20)^7)*(18.5%+(F15-18.5%)*7/7)/(1+DCF!$B$97)^9.5+((DCF!H71*(1+A20)^7)*(18.5%+(F15-18.5%)*7/7)*(1+DCF!$B$98)/(DCF!$B$97-DCF!$B$98))/(1+DCF!$B$97)^9.5+DCF!$B$10-DCF!$B$11)/DCF!$B$9
A24: Beta vs Risk-Free Rate
A25: Beta \ Risk-free | B25: 0.035 | C25: 0.0385 | D25: 0.042 | E25: 0.0455 | F25: 0.049
A26: 0.9 | B26: =(DCF!F82/(1+(B25+A26*0.05))^0.5+DCF!G82/(1+(B25+A26*0.05))^1.5+DCF!H82/(1+(B25+A26*0.05))^2.5+DCF!I82/(1+(B25+A26*0.05))^3.5+DCF!J82/(1+(B25+A26*0.05))^4.5+DCF!K82/(1+(B25+A26*0.05))^5.5+DCF!L82/(1+(B25+A26*0.05))^6.5+DCF!M82/(1+(B25+A26*0.05))^7.5+DCF!N82/(1+(B25+A26*0.05))^8.5+DCF!O82/(1+(B25+A26*0.05))^9.5+(DCF!O82*(1+DCF!$B$98)/((B25+A26*0.05)-DCF!$B$98))/(1+(B25+A26*0.05))^9.5+DCF!$B$10-DCF!$B$11)/DCF!$B$9 | C26: =(DCF!F82/(1+(C25+A26*0.05))^0.5+DCF!G82/(1+(C25+A26*0.05))^1.5+DCF!H82/(1+(C25+A26*0.05))^2.5+DCF!I82/(1+(C25+A26*0.05))^3.5+DCF!J82/(1+(C25+A26*0.05))^4.5+DCF!K82/(1+(C25+A26*0.05))^5.5+DCF!L82/(1+(C25+A26*0.05))^6.5+DCF!M82/(1+(C25+A26*0.05))^7.5+DCF!N82/(1+(C25+A26*0.05))^8.5+DCF!O82/(1+(C25+A26*0.05))^9.5+(DCF!O82*(1+DCF!$B$98)/((C25+A26*0.05)-DCF!$B$98))/(1+(C25+A26*0.05))^9.5+DCF!$B$10-DCF!$B$11)/DCF!$B$9 | D26: =(DCF!F82/(1+(D25+A26*0.05))^0.5+DCF!G82/(1+(D25+A26*0.05))^1.5+DCF!H82/(1+(D25+A26*0.05))^2.5+DCF!I82/(1+(D25+A26*0.05))^3.5+DCF!J82/(1+(D25+A26*0.05))^4.5+DCF!K82/(1+(D25+A26*0.05))^5.5+DCF!L82/(1+(D25+A26*0.05))^6.5+DCF!M82/(1+(D25+A26*0.05))^7.5+DCF!N82/(1+(D25+A26*0.05))^8.5+DCF!O82/(1+(D25+A26*0.05))^9.5+(DCF!O82*(1+DCF!$B$98)/((D25+A26*0.05)-DCF!$B$98))/(1+(D25+A26*0.05))^9.5+DCF!$B$10-DCF!$B$11)/DCF!$B$9 | E26: =(DCF!F82/(1+(E25+A26*0.05))^0.5+DCF!G82/(1+(E25+A26*0.05))^1.5+DCF!H82/(1+(E25+A26*0.05))^2.5+DCF!I82/(1+(E25+A26*0.05))^3.5+DCF!J82/(1+(E25+A26*0.05))^4.5+DCF!K82/(1+(E25+A26*0.05))^5.5+DCF!L82/(1+(E25+A26*0.05))^6.5+DCF!M82/(1+(E25+A26*0.05))^7.5+DCF!N82/(1+(E25+A26*0.05))^8.5+DCF!O82/(1+(E25+A26*0.05))^9.5+(DCF!O82*(1+DCF!$B$98)/((E25+A26*0.05)-DCF!$B$98))/(1+(E25+A26*0.05))^9.5+DCF!$B$10-DCF!$B$11)/DCF!$B$9 | F26: =(DCF!F82/(1+(F25+A26*0.05))^0.5+DCF!G82/(1+(F25+A26*0.05))^1.5+DCF!H82/(1+(F25+A26*0.05))^2.5+DCF!I82/(1+(F25+A26*0.05))^3.5+DCF!J82/(1+(F25+A26*0.05))^4.5+DCF!K82/(1+(F25+A26*0.05))^5.5+DCF!L82/(1+(F25+A26*0.05))^6.5+DCF!M82/(1+(F25+A26*0.05))^7.5+DCF!N82/(1+(F25+A26*0.05))^8.5+DCF!O82/(1+(F25+A26*0.05))^9.5+(DCF!O82*(1+DCF!$B$98)/((F25+A26*0.05)-DCF!$B$98))/(1+(F25+A26*0.05))^9.5+DCF!$B$10-DCF!$B$11)/DCF!$B$9
A27: 1 | B27: =(DCF!F82/(1+(B25+A27*0.05))^0.5+DCF!G82/(1+(B25+A27*0.05))^1.5+DCF!H82/(1+(B25+A27*0.05))^2.5+DCF!I82/(1+(B25+A27*0.05))^3.5+DCF!J82/(1+(B25+A27*0.05))^4.5+DCF!K82/(1+(B25+A27*0.05))^5.5+DCF!L82/(1+(B25+A27*0.05))^6.5+DCF!M82/(1+(B25+A27*0.05))^7.5+DCF!N82/(1+(B25+A27*0.05))^8.5+DCF!O82/(1+(B25+A27*0.05))^9.5+(DCF!O82*(1+DCF!$B$98)/((B25+A27*0.05)-DCF!$B$98))/(1+(B25+A27*0.05))^9.5+DCF!$B$10-DCF!$B$11)/DCF!$B$9 | C27: =(DCF!F82/(1+(C25+A27*0.05))^0.5+DCF!G82/(1+(C25+A27*0.05))^1.5+DCF!H82/(1+(C25+A27*0.05))^2.5+DCF!I82/(1+(C25+A27*0.05))^3.5+DCF!J82/(1+(C25+A27*0.05))^4.5+DCF!K82/(1+(C25+A27*0.05))^5.5+DCF!L82/(1+(C25+A27*0.05))^6.5+DCF!M82/(1+(C25+A27*0.05))^7.5+DCF!N82/(1+(C25+A27*0.05))^8.5+DCF!O82/(1+(C25+A27*0.05))^9.5+(DCF!O82*(1+DCF!$B$98)/((C25+A27*0.05)-DCF!$B$98))/(1+(C25+A27*0.05))^9.5+DCF!$B$10-DCF!$B$11)/DCF!$B$9 | D27: =(DCF!F82/(1+(D25+A27*0.05))^0.5+DCF!G82/(1+(D25+A27*0.05))^1.5+DCF!H82/(1+(D25+A27*0.05))^2.5+DCF!I82/(1+(D25+A27*0.05))^3.5+DCF!J82/(1+(D25+A27*0.05))^4.5+DCF!K82/(1+(D25+A27*0.05))^5.5+DCF!L82/(1+(D25+A27*0.05))^6.5+DCF!M82/(1+(D25+A27*0.05))^7.5+DCF!N82/(1+(D25+A27*0.05))^8.5+DCF!O82/(1+(D25+A27*0.05))^9.5+(DCF!O82*(1+DCF!$B$98)/((D25+A27*0.05)-DCF!$B$98))/(1+(D25+A27*0.05))^9.5+DCF!$B$10-DCF!$B$11)/DCF!$B$9 | E27: =(DCF!F82/(1+(E25+A27*0.05))^0.5+DCF!G82/(1+(E25+A27*0.05))^1.5+DCF!H82/(1+(E25+A27*0.05))^2.5+DCF!I82/(1+(E25+A27*0.05))^3.5+DCF!J82/(1+(E25+A27*0.05))^4.5+DCF!K82/(1+(E25+A27*0.05))^5.5+DCF!L82/(1+(E25+A27*0.05))^6.5+DCF!M82/(1+(E25+A27*0.05))^7.5+DCF!N82/(1+(E25+A27*0.05))^8.5+DCF!O82/(1+(E25+A27*0.05))^9.5+(DCF!O82*(1+DCF!$B$98)/((E25+A27*0.05)-DCF!$B$98))/(1+(E25+A27*0.05))^9.5+DCF!$B$10-DCF!$B$11)/DCF!$B$9 | F27: =(DCF!F82/(1+(F25+A27*0.05))^0.5+DCF!G82/(1+(F25+A27*0.05))^1.5+DCF!H82/(1+(F25+A27*0.05))^2.5+DCF!I82/(1+(F25+A27*0.05))^3.5+DCF!J82/(1+(F25+A27*0.05))^4.5+DCF!K82/(1+(F25+A27*0.05))^5.5+DCF!L82/(1+(F25+A27*0.05))^6.5+DCF!M82/(1+(F25+A27*0.05))^7.5+DCF!N82/(1+(F25+A27*0.05))^8.5+DCF!O82/(1+(F25+A27*0.05))^9.5+(DCF!O82*(1+DCF!$B$98)/((F25+A27*0.05)-DCF!$B$98))/(1+(F25+A27*0.05))^9.5+DCF!$B$10-DCF!$B$11)/DCF!$B$9
A28: 1.1 | B28: =(DCF!F82/(1+(B25+A28*0.05))^0.5+DCF!G82/(1+(B25+A28*0.05))^1.5+DCF!H82/(1+(B25+A28*0.05))^2.5+DCF!I82/(1+(B25+A28*0.05))^3.5+DCF!J82/(1+(B25+A28*0.05))^4.5+DCF!K82/(1+(B25+A28*0.05))^5.5+DCF!L82/(1+(B25+A28*0.05))^6.5+DCF!M82/(1+(B25+A28*0.05))^7.5+DCF!N82/(1+(B25+A28*0.05))^8.5+DCF!O82/(1+(B25+A28*0.05))^9.5+(DCF!O82*(1+DCF!$B$98)/((B25+A28*0.05)-DCF!$B$98))/(1+(B25+A28*0.05))^9.5+DCF!$B$10-DCF!$B$11)/DCF!$B$9 | C28: =(DCF!F82/(1+(C25+A28*0.05))^0.5+DCF!G82/(1+(C25+A28*0.05))^1.5+DCF!H82/(1+(C25+A28*0.05))^2.5+DCF!I82/(1+(C25+A28*0.05))^3.5+DCF!J82/(1+(C25+A28*0.05))^4.5+DCF!K82/(1+(C25+A28*0.05))^5.5+DCF!L82/(1+(C25+A28*0.05))^6.5+DCF!M82/(1+(C25+A28*0.05))^7.5+DCF!N82/(1+(C25+A28*0.05))^8.5+DCF!O82/(1+(C25+A28*0.05))^9.5+(DCF!O82*(1+DCF!$B$98)/((C25+A28*0.05)-DCF!$B$98))/(1+(C25+A28*0.05))^9.5+DCF!$B$10-DCF!$B$11)/DCF!$B$9 | D28: =(DCF!F82/(1+(D25+A28*0.05))^0.5+DCF!G82/(1+(D25+A28*0.05))^1.5+DCF!H82/(1+(D25+A28*0.05))^2.5+DCF!I82/(1+(D25+A28*0.05))^3.5+DCF!J82/(1+(D25+A28*0.05))^4.5+DCF!K82/(1+(D25+A28*0.05))^5.5+DCF!L82/(1+(D25+A28*0.05))^6.5+DCF!M82/(1+(D25+A28*0.05))^7.5+DCF!N82/(1+(D25+A28*0.05))^8.5+DCF!O82/(1+(D25+A28*0.05))^9.5+(DCF!O82*(1+DCF!$B$98)/((D25+A28*0.05)-DCF!$B$98))/(1+(D25+A28*0.05))^9.5+DCF!$B$10-DCF!$B$11)/DCF!$B$9 | E28: =(DCF!F82/(1+(E25+A28*0.05))^0.5+DCF!G82/(1+(E25+A28*0.05))^1.5+DCF!H82/(1+(E25+A28*0.05))^2.5+DCF!I82/(1+(E25+A28*0.05))^3.5+DCF!J82/(1+(E25+A28*0.05))^4.5+DCF!K82/(1+(E25+A28*0.05))^5.5+DCF!L82/(1+(E25+A28*0.05))^6.5+DCF!M82/(1+(E25+A28*0.05))^7.5+DCF!N82/(1+(E25+A28*0.05))^8.5+DCF!O82/(1+(E25+A28*0.05))^9.5+(DCF!O82*(1+DCF!$B$98)/((E25+A28*0.05)-DCF!$B$98))/(1+(E25+A28*0.05))^9.5+DCF!$B$10-DCF!$B$11)/DCF!$B$9 | F28: =(DCF!F82/(1+(F25+A28*0.05))^0.5+DCF!G82/(1+(F25+A28*0.05))^1.5+DCF!H82/(1+(F25+A28*0.05))^2.5+DCF!I82/(1+(F25+A28*0.05))^3.5+DCF!J82/(1+(F25+A28*0.05))^4.5+DCF!K82/(1+(F25+A28*0.05))^5.5+DCF!L82/(1+(F25+A28*0.05))^6.5+DCF!M82/(1+(F25+A28*0.05))^7.5+DCF!N82/(1+(F25+A28*0.05))^8.5+DCF!O82/(1+(F25+A28*0.05))^9.5+(DCF!O82*(1+DCF!$B$98)/((F25+A28*0.05)-DCF!$B$98))/(1+(F25+A28*0.05))^9.5+DCF!$B$10-DCF!$B$11)/DCF!$B$9
A29: 1.2 | B29: =(DCF!F82/(1+(B25+A29*0.05))^0.5+DCF!G82/(1+(B25+A29*0.05))^1.5+DCF!H82/(1+(B25+A29*0.05))^2.5+DCF!I82/(1+(B25+A29*0.05))^3.5+DCF!J82/(1+(B25+A29*0.05))^4.5+DCF!K82/(1+(B25+A29*0.05))^5.5+DCF!L82/(1+(B25+A29*0.05))^6.5+DCF!M82/(1+(B25+A29*0.05))^7.5+DCF!N82/(1+(B25+A29*0.05))^8.5+DCF!O82/(1+(B25+A29*0.05))^9.5+(DCF!O82*(1+DCF!$B$98)/((B25+A29*0.05)-DCF!$B$98))/(1+(B25+A29*0.05))^9.5+DCF!$B$10-DCF!$B$11)/DCF!$B$9 | C29: =(DCF!F82/(1+(C25+A29*0.05))^0.5+DCF!G82/(1+(C25+A29*0.05))^1.5+DCF!H82/(1+(C25+A29*0.05))^2.5+DCF!I82/(1+(C25+A29*0.05))^3.5+DCF!J82/(1+(C25+A29*0.05))^4.5+DCF!K82/(1+(C25+A29*0.05))^5.5+DCF!L82/(1+(C25+A29*0.05))^6.5+DCF!M82/(1+(C25+A29*0.05))^7.5+DCF!N82/(1+(C25+A29*0.05))^8.5+DCF!O82/(1+(C25+A29*0.05))^9.5+(DCF!O82*(1+DCF!$B$98)/((C25+A29*0.05)-DCF!$B$98))/(1+(C25+A29*0.05))^9.5+DCF!$B$10-DCF!$B$11)/DCF!$B$9 | D29: =(DCF!F82/(1+(D25+A29*0.05))^0.5+DCF!G82/(1+(D25+A29*0.05))^1.5+DCF!H82/(1+(D25+A29*0.05))^2.5+DCF!I82/(1+(D25+A29*0.05))^3.5+DCF!J82/(1+(D25+A29*0.05))^4.5+DCF!K82/(1+(D25+A29*0.05))^5.5+DCF!L82/(1+(D25+A29*0.05))^6.5+DCF!M82/(1+(D25+A29*0.05))^7.5+DCF!N82/(1+(D25+A29*0.05))^8.5+DCF!O82/(1+(D25+A29*0.05))^9.5+(DCF!O82*(1+DCF!$B$98)/((D25+A29*0.05)-DCF!$B$98))/(1+(D25+A29*0.05))^9.5+DCF!$B$10-DCF!$B$11)/DCF!$B$9 | E29: =(DCF!F82/(1+(E25+A29*0.05))^0.5+DCF!G82/(1+(E25+A29*0.05))^1.5+DCF!H82/(1+(E25+A29*0.05))^2.5+DCF!I82/(1+(E25+A29*0.05))^3.5+DCF!J82/(1+(E25+A29*0.05))^4.5+DCF!K82/(1+(E25+A29*0.05))^5.5+DCF!L82/(1+(E25+A29*0.05))^6.5+DCF!M82/(1+(E25+A29*0.05))^7.5+DCF!N82/(1+(E25+A29*0.05))^8.5+DCF!O82/(1+(E25+A29*0.05))^9.5+(DCF!O82*(1+DCF!$B$98)/((E25+A29*0.05)-DCF!$B$98))/(1+(E25+A29*0.05))^9.5+DCF!$B$10-DCF!$B$11)/DCF!$B$9 | F29: =(DCF!F82/(1+(F25+A29*0.05))^0.5+DCF!G82/(1+(F25+A29*0.05))^1.5+DCF!H82/(1+(F25+A29*0.05))^2.5+DCF!I82/(1+(F25+A29*0.05))^3.5+DCF!J82/(1+(F25+A29*0.05))^4.5+DCF!K82/(1+(F25+A29*0.05))^5.5+DCF!L82/(1+(F25+A29*0.05))^6.5+DCF!M82/(1+(F25+A29*0.05))^7.5+DCF!N82/(1+(F25+A29*0.05))^8.5+DCF!O82/(1+(F25+A29*0.05))^9.5+(DCF!O82*(1+DCF!$B$98)/((F25+A29*0.05)-DCF!$B$98))/(1+(F25+A29*0.05))^9.5+DCF!$B$10-DCF!$B$11)/DCF!$B$9
A30: 1.3 | B30: =(DCF!F82/(1+(B25+A30*0.05))^0.5+DCF!G82/(1+(B25+A30*0.05))^1.5+DCF!H82/(1+(B25+A30*0.05))^2.5+DCF!I82/(1+(B25+A30*0.05))^3.5+DCF!J82/(1+(B25+A30*0.05))^4.5+DCF!K82/(1+(B25+A30*0.05))^5.5+DCF!L82/(1+(B25+A30*0.05))^6.5+DCF!M82/(1+(B25+A30*0.05))^7.5+DCF!N82/(1+(B25+A30*0.05))^8.5+DCF!O82/(1+(B25+A30*0.05))^9.5+(DCF!O82*(1+DCF!$B$98)/((B25+A30*0.05)-DCF!$B$98))/(1+(B25+A30*0.05))^9.5+DCF!$B$10-DCF!$B$11)/DCF!$B$9 | C30: =(DCF!F82/(1+(C25+A30*0.05))^0.5+DCF!G82/(1+(C25+A30*0.05))^1.5+DCF!H82/(1+(C25+A30*0.05))^2.5+DCF!I82/(1+(C25+A30*0.05))^3.5+DCF!J82/(1+(C25+A30*0.05))^4.5+DCF!K82/(1+(C25+A30*0.05))^5.5+DCF!L82/(1+(C25+A30*0.05))^6.5+DCF!M82/(1+(C25+A30*0.05))^7.5+DCF!N82/(1+(C25+A30*0.05))^8.5+DCF!O82/(1+(C25+A30*0.05))^9.5+(DCF!O82*(1+DCF!$B$98)/((C25+A30*0.05)-DCF!$B$98))/(1+(C25+A30*0.05))^9.5+DCF!$B$10-DCF!$B$11)/DCF!$B$9 | D30: =(DCF!F82/(1+(D25+A30*0.05))^0.5+DCF!G82/(1+(D25+A30*0.05))^1.5+DCF!H82/(1+(D25+A30*0.05))^2.5+DCF!I82/(1+(D25+A30*0.05))^3.5+DCF!J82/(1+(D25+A30*0.05))^4.5+DCF!K82/(1+(D25+A30*0.05))^5.5+DCF!L82/(1+(D25+A30*0.05))^6.5+DCF!M82/(1+(D25+A30*0.05))^7.5+DCF!N82/(1+(D25+A30*0.05))^8.5+DCF!O82/(1+(D25+A30*0.05))^9.5+(DCF!O82*(1+DCF!$B$98)/((D25+A30*0.05)-DCF!$B$98))/(1+(D25+A30*0.05))^9.5+DCF!$B$10-DCF!$B$11)/DCF!$B$9 | E30: =(DCF!F82/(1+(E25+A30*0.05))^0.5+DCF!G82/(1+(E25+A30*0.05))^1.5+DCF!H82/(1+(E25+A30*0.05))^2.5+DCF!I82/(1+(E25+A30*0.05))^3.5+DCF!J82/(1+(E25+A30*0.05))^4.5+DCF!K82/(1+(E25+A30*0.05))^5.5+DCF!L82/(1+(E25+A30*0.05))^6.5+DCF!M82/(1+(E25+A30*0.05))^7.5+DCF!N82/(1+(E25+A30*0.05))^8.5+DCF!O82/(1+(E25+A30*0.05))^9.5+(DCF!O82*(1+DCF!$B$98)/((E25+A30*0.05)-DCF!$B$98))/(1+(E25+A30*0.05))^9.5+DCF!$B$10-DCF!$B$11)/DCF!$B$9 | F30: =(DCF!F82/(1+(F25+A30*0.05))^0.5+DCF!G82/(1+(F25+A30*0.05))^1.5+DCF!H82/(1+(F25+A30*0.05))^2.5+DCF!I82/(1+(F25+A30*0.05))^3.5+DCF!J82/(1+(F25+A30*0.05))^4.5+DCF!K82/(1+(F25+A30*0.05))^5.5+DCF!L82/(1+(F25+A30*0.05))^6.5+DCF!M82/(1+(F25+A30*0.05))^7.5+DCF!N82/(1+(F25+A30*0.05))^8.5+DCF!O82/(1+(F25+A30*0.05))^9.5+(DCF!O82*(1+DCF!$B$98)/((F25+A30*0.05)-DCF!$B$98))/(1+(F25+A30*0.05))^9.5+DCF!$B$10-DCF!$B$11)/DCF!$B$9

Sheet Comps
A1: Comparable Companies and Multiples
A3: Company | B3: Ticker | C3: Category | D3: EV/Sales NTM | E3: EV/EBITDA | F3: Gross margin | G3: Notes
A4: Shopify | B4: SHOP | C4: Commerce infrastructure | D4: 8.3 | E4: 44.4 | F4: 0.48 | G4: Koyfin current
A5: Wix | B5: WIX | C5: SMB web/commerce | D5: 2.4 | E5: 13.4 | F5: 0.67 | G5: Public comp
A6: BigCommerce | B6: BIGC | C6: Commerce software | D6: 2.5 | F6: 0.78 | G6: Smaller commerce SaaS
A7: GoDaddy | B7: GDDY | C7: Domains/commerce | D7: 4.5 | E7: 15 | F7: 0.63 | G7: Broader SMB platform
A8: MercadoLibre | B8: MELI | C8: Marketplace/fintech | D8: 3.5 | E8: 20 | F8: 0.5 | G8: Commerce ecosystem

Sheet Thesis Tracker
A1: Thesis Tracker
A3: Pillar | B3: Evidence | C3: KPI | D3: Current | E3: Bull trigger | F3: Bear trigger | G3: Model impact
A4: Commerce operating system | B4: $378B FY2025 GMV; $100.7B Q1 GMV | C4: GMV growth | D4: Q1 +35% | E4: >25% sustained | F4: <18% | G4: Revenue growth
A5: Merchant Solutions flywheel | B5: GPV penetration 67%; Merchant Solutions +39% | C5: GPV penetration | D5: 67% | E5: >75% | F5: Stalls <67% | G5: Take rate / gross margin
A6: Upmarket runway | B6: Plus, B2B, enterprise wins | C6: Plus MRR / B2B GMV | D6: Plus ~34% MRR | E6: B2B >50% | F6: Enterprise stalls | G6: Growth duration
A7: FCF durability | B7: FY2025 FCF $2.0B | C7: FCF margin | D7: 15-17% | E7: >20% | F7: <12% | G7: Terminal FCF margin
A8: AI option | B8: UCP, Sidekick, Catalog | C8: AI-referred GMV | D8: Early | E8: Disclosed material GMV | F8: Bypass risk | G8: Bull scenario

Sheet DCF Assumptions
A1: DCF Assumptions Register
A3: Assumption | B3: Base | C3: Bear | D3: Bull | E3: Rationale
A4: WACC | B4: 9.5% | C4: 10.5% | D4: 8.5% | E4: Adjusted beta / CAPM; net cash capital structure
A5: Terminal growth | B5: 3.5% | C5: 2.5% | D5: 4.5% | E5: Global ecommerce + inflation; sensitivity key
A6: Terminal FCF margin | B6: 22.0% | C6: 18.0% | D6: 26.5% | E6: Operating leverage vs Merchant Solutions mix pressure
A7: FY2026 revenue | B7: $14.8B | C7: $14.3B | D7: $15.2B | E7: Koyfin consensus anchored
A8: Gross margin | B8: 48.5% near-term | C8: 47% | D8: 49.5% | E8: Subscription vs Merchant mix
A9: SBC treatment | B9: Economic cost via dilution/buyback | C9: Higher dilution | D9: Buyback offsets | E9: Track share count

Sheet Checks
A1: Model Checks
A3: Check | B3: Formula | C3: Status
A4: Terminal growth < WACC | B4: =DCF!B98<DCF!B97 | C4: =IF(B4,"OK","CHECK")
A5: DCF center sensitivity ties to DCF output | B5: =ABS(Sensitivity!D8-DCF!B107)<1 | C5: =IF(B5,"OK","CHECK")
A6: Equity bridge positive | B6: =DCF!B105>0 | C6: =IF(B6,"OK","CHECK")
A7: Terminal value share of EV reasonable | B7: =DCF!B101/DCF!B102<0.8 | C7: =IF(B7,"OK","CHECK")
A8: Projected FCF positive | B8: =MIN(DCF!F82:O82)>0 | C8: =IF(B8,"OK","CHECK")
